<?xml version="1.0" ?>
<!-- =================================================================================== -->
<!-- |    This document was autogenerated by xacro from qronk.urdf.xacro               | -->
<!-- |    EDITING THIS FILE BY HAND IS NOT RECOMMENDED                                 | -->
<!-- =================================================================================== -->
<robot name="qronk">
  <link name="base_link"/>
  <!-- RVIZ COLORS -->
  <material name="red">
    <color rgba="0.5 0 0 1"/>
  </material>
  <material name="green">
    <color rgba="0 0.5 0 1"/>
  </material>
  <material name="blue">
    <color rgba="0 0 0.5 1"/>
  </material>
  <material name="grey">
    <color rgba="0.5 0.5 0.5 1"/>
  </material>
  <!-- XACRO INERTIA MACROS -->
  <joint name="base_chassis_joint" type="fixed">
    <parent link="base_link"/>
    <child link="chassis_link"/>
    <origin rpy="0 0 0" xyz="0 0 0"/>
  </joint>
  <link name="chassis_link">
    <visual>
      <geometry>
        <mesh filename="package://qronk_description/meshes/chassis.stl" scale="0.001 0.001 0.001"/>
      </geometry>
      <origin rpy="0 0 0" xyz="0 0 0"/>
      <material name="grey"/>
    </visual>
    <collision>
      <geometry>
        <box size="0.185 0.136835 0.084144"/>
      </geometry>
      <origin rpy="0 0 0" xyz="0 0 0.003928"/>
    </collision>
    <inertial>
      <origin rpy="0 0 0" xyz="0 0 0.004"/>
      <mass value="0.3"/>
      <inertia ixx="0.001032025" ixy="0" ixz="0" iyy="0.0013248499999999998" iyz="0" izz="0.000645625"/>
    </inertial>
  </link>
  <joint name="chassis_battery_joint" type="fixed">
    <parent link="chassis_link"/>
    <child link="battery_link"/>
    <origin rpy="0 0 0" xyz="0 0 -0.0305"/>
  </joint>
  <link name="battery_link">
    <visual>
      <geometry>
        <mesh filename="package://qronk_description/meshes/battery.stl" scale="0.001 0.001 0.001"/>
      </geometry>
      <origin rpy="0 0 0" xyz="-0.069 -0.0225 0"/>
      <material name="grey"/>
    </visual>
    <collision>
      <geometry>
        <box size="0.138 0.045 0.018"/>
      </geometry>
      <origin rpy="0 0 0" xyz="0 0 0.009"/>
    </collision>
    <inertial>
      <origin rpy="0 0 0" xyz="0 0 0.009"/>
      <mass value="0.35"/>
      <inertia ixx="0.0005649" ixy="0" ixz="0" iyy="0.0006145125" iyz="0" izz="6.851249999999999e-05"/>
    </inertial>
  </link>
  <joint name="chassis_raspberry_joint" type="fixed">
    <parent link="chassis_link"/>
    <child link="raspberry_link"/>
    <origin rpy="0 0 0" xyz="0 0 0.044"/>
  </joint>
  <link name="raspberry_link">
    <visual>
      <geometry>
        <mesh filename="package://qronk_description/meshes/raspberry.stl" scale="0.001 0.001 0.001"/>
      </geometry>
      <origin rpy="0 0 0" xyz="-0.05 -0.035 0"/>
      <material name="grey"/>
    </visual>
    <collision>
      <geometry>
        <box size="0.1 0.07 0.025"/>
      </geometry>
      <origin rpy="0 0 0" xyz="0 0 0.0125"/>
    </collision>
    <inertial>
      <origin rpy="0 0 0" xyz="0 0 0.0125"/>
      <mass value="0.15"/>
      <inertia ixx="0.00013281250000000004" ixy="0" ixz="0" iyy="0.00018625000000000003" iyz="0" izz="6.90625e-05"/>
    </inertial>
  </link>
  <joint name="chassis_shoulder_FR_joint" type="revolute">
    <parent link="chassis_link"/>
    <child link="shoulder_FR_link"/>
    <origin rpy="0 0 0" xyz="0.0885 -0.047417 0.000052"/>
    <axis xyz="1 0 0"/>
    <limit effort="100" lower="-3.141592653589793" upper="3.141592653589793" velocity="100"/>
  </joint>
  <link name="shoulder_FR_link">
    <visual>
      <geometry>
        <mesh filename="package://qronk_description/meshes/shoulder_FR.stl" scale="0.001 0.001 0.001"/>
      </geometry>
      <origin rpy="0 0 0" xyz="0 0 0"/>
      <material name="grey"/>
    </visual>
    <collision>
      <geometry>
        <box size="0.05 0.04 0.068"/>
      </geometry>
      <origin rpy="0 0 0" xyz="0.03 0 -0.005"/>
    </collision>
    <inertial>
      <origin rpy="0 0 0" xyz="0.03 0 -0.005"/>
      <mass value="0.1"/>
      <inertia ixx="5.936666666666668e-05" ixy="0" ixz="0" iyy="3.416666666666667e-05" iyz="0" izz="5.186666666666667e-05"/>
    </inertial>
  </link>
  <joint name="shoulder_upper_leg_FR_joint" type="revolute">
    <parent link="shoulder_FR_link"/>
    <child link="upper_leg_FR_link"/>
    <origin rpy="0 0 0" xyz="0.03 -0.0214 -0.00002"/>
    <axis xyz="0 1 0"/>
    <limit effort="100" lower="-3.141592653589793" upper="3.141592653589793" velocity="100"/>
  </joint>
  <link name="upper_leg_FR_link">
    <visual>
      <geometry>
        <mesh filename="package://qronk_description/meshes/upper_leg_FR.stl" scale="0.001 0.001 0.001"/>
      </geometry>
      <origin rpy="0 0 0" xyz="0 0 0"/>
      <material name="grey"/>
    </visual>
    <collision>
      <geometry>
        <box size="0.05 0.0532 0.137"/>
      </geometry>
      <origin rpy="0 0 0" xyz="0 -0.0266 -0.0435"/>
    </collision>
    <inertial>
      <origin rpy="0 0 0" xyz="0 -0.0266 -0.0435"/>
      <mass value="0.1"/>
      <inertia ixx="2.239741666666667e-05" ixy="0" ixz="0" iyy="4.441866666666667e-05" iyz="0" izz="2.5149416666666667e-05"/>
    </inertial>
  </link>
  <joint name="upper_leg_lower_leg_FR_joint" type="revolute">
    <parent link="upper_leg_FR_link"/>
    <child link="lower_leg_FR_link"/>
    <origin rpy="0 0 0" xyz="0 -0.016349 -0.098459"/>
    <axis xyz="0 1 0"/>
    <limit effort="100" lower="-3.141592653589793" upper="3.141592653589793" velocity="100"/>
  </joint>
  <link name="lower_leg_FR_link">
    <visual>
      <geometry>
        <mesh filename="package://qronk_description/meshes/lower_leg_FR.stl" scale="0.001 0.001 0.001"/>
      </geometry>
      <origin rpy="0 0 0" xyz="0 0 0"/>
      <material name="grey"/>
    </visual>
    <collision>
      <geometry>
        <box size="0.028 0.0134 0.102"/>
      </geometry>
      <origin rpy="0 0 0" xyz="0 -0.0067 -0.037"/>
    </collision>
    <inertial>
      <origin rpy="0 0 0" xyz="0 -0.0067 -0.037"/>
      <mass value="0.1"/>
      <inertia ixx="9.323333333333333e-05" ixy="0" ixz="0" iyy="8.029666666666669e-06" iyz="0" izz="8.819633333333333e-05"/>
    </inertial>
  </link>
  <joint name="lower_leg_foot_FR_joint" type="fixed">
    <parent link="lower_leg_FR_link"/>
    <child link="foot_FR_link"/>
    <origin rpy="0 0 0" xyz="0 -0.0066835 -0.09416"/>
  </joint>
  <link name="foot_FR_link">
    <visual>
      <geometry>
        <sphere radius="0.0075"/>
      </geometry>
      <origin rpy="0 0 0" xyz="0 0 0"/>
      <material name="grey"/>
    </visual>
    <collision>
      <geometry>
        <sphere radius="0.0075"/>
      </geometry>
      <origin rpy="0 0 0" xyz="0 0 0"/>
    </collision>
    <inertial>
      <origin rpy="0 0 0" xyz="0 0 0"/>
      <mass value="0.05"/>
      <inertia ixx="1.125e-06" ixy="0" ixz="0" iyy="1.125e-06" iyz="0" izz="1.125e-06"/>
    </inertial>
  </link>
  <joint name="chassis_shoulder_FL_joint" type="revolute">
    <parent link="chassis_link"/>
    <child link="shoulder_FL_link"/>
    <origin rpy="0 0 0" xyz="0.0885 0.047417 0.000052"/>
    <axis xyz="1 0 0"/>
    <limit effort="100" lower="-3.141592653589793" upper="3.141592653589793" velocity="100"/>
  </joint>
  <link name="shoulder_FL_link">
    <visual>
      <geometry>
        <mesh filename="package://qronk_description/meshes/shoulder_FL.stl" scale="0.001 0.001 0.001"/>
      </geometry>
      <origin rpy="0 0 0" xyz="0 0 0"/>
      <material name="grey"/>
    </visual>
    <collision>
      <geometry>
        <box size="0.05 0.04 0.068"/>
      </geometry>
      <origin rpy="0 0 0" xyz="0.03 -0 -0.005"/>
    </collision>
    <inertial>
      <origin rpy="0 0 0" xyz="0.03 -0 -0.005"/>
      <mass value="0.1"/>
      <inertia ixx="5.936666666666668e-05" ixy="0" ixz="0" iyy="3.416666666666667e-05" iyz="0" izz="5.186666666666667e-05"/>
    </inertial>
  </link>
  <joint name="shoulder_upper_leg_FL_joint" type="revolute">
    <parent link="shoulder_FL_link"/>
    <child link="upper_leg_FL_link"/>
    <origin rpy="0 0 0" xyz="0.03 0.0214 -0.00002"/>
    <axis xyz="0 1 0"/>
    <limit effort="100" lower="-3.141592653589793" upper="3.141592653589793" velocity="100"/>
  </joint>
  <link name="upper_leg_FL_link">
    <visual>
      <geometry>
        <mesh filename="package://qronk_description/meshes/upper_leg_FL.stl" scale="0.001 0.001 0.001"/>
      </geometry>
      <origin rpy="0 0 0" xyz="0 0 0"/>
      <material name="grey"/>
    </visual>
    <collision>
      <geometry>
        <box size="0.05 0.0532 0.137"/>
      </geometry>
      <origin rpy="0 0 0" xyz="0 0.0266 -0.0435"/>
    </collision>
    <inertial>
      <origin rpy="0 0 0" xyz="0 0.0266 -0.0435"/>
      <mass value="0.1"/>
      <inertia ixx="2.239741666666667e-05" ixy="0" ixz="0" iyy="4.441866666666667e-05" iyz="0" izz="2.5149416666666667e-05"/>
    </inertial>
  </link>
  <joint name="upper_leg_lower_leg_FL_joint" type="revolute">
    <parent link="upper_leg_FL_link"/>
    <child link="lower_leg_FL_link"/>
    <origin rpy="0 0 0" xyz="0 0.016349 -0.098459"/>
    <axis xyz="0 1 0"/>
    <limit effort="100" lower="-3.141592653589793" upper="3.141592653589793" velocity="100"/>
  </joint>
  <link name="lower_leg_FL_link">
    <visual>
      <geometry>
        <mesh filename="package://qronk_description/meshes/lower_leg_FL.stl" scale="0.001 0.001 0.001"/>
      </geometry>
      <origin rpy="0 0 0" xyz="0 0 0"/>
      <material name="grey"/>
    </visual>
    <collision>
      <geometry>
        <box size="0.028 0.0134 0.102"/>
      </geometry>
      <origin rpy="0 0 0" xyz="0 0.0067 -0.037"/>
    </collision>
    <inertial>
      <origin rpy="0 0 0" xyz="0 0.0067 -0.037"/>
      <mass value="0.1"/>
      <inertia ixx="9.323333333333333e-05" ixy="0" ixz="0" iyy="8.029666666666669e-06" iyz="0" izz="8.819633333333333e-05"/>
    </inertial>
  </link>
  <joint name="lower_leg_foot_FL_joint" type="fixed">
    <parent link="lower_leg_FL_link"/>
    <child link="foot_FL_link"/>
    <origin rpy="0 0 0" xyz="0 0.0066835 -0.09416"/>
  </joint>
  <link name="foot_FL_link">
    <visual>
      <geometry>
        <sphere radius="0.0075"/>
      </geometry>
      <origin rpy="0 0 0" xyz="0 0 0"/>
      <material name="grey"/>
    </visual>
    <collision>
      <geometry>
        <sphere radius="0.0075"/>
      </geometry>
      <origin rpy="0 0 0" xyz="0 0 0"/>
    </collision>
    <inertial>
      <origin rpy="0 0 0" xyz="0 0 0"/>
      <mass value="0.05"/>
      <inertia ixx="1.125e-06" ixy="0" ixz="0" iyy="1.125e-06" iyz="0" izz="1.125e-06"/>
    </inertial>
  </link>
  <joint name="chassis_shoulder_BR_joint" type="revolute">
    <parent link="chassis_link"/>
    <child link="shoulder_BR_link"/>
    <origin rpy="0 0 0" xyz="-0.0885 -0.047417 0.000052"/>
    <axis xyz="1 0 0"/>
    <limit effort="100" lower="-3.141592653589793" upper="3.141592653589793" velocity="100"/>
  </joint>
  <link name="shoulder_BR_link">
    <visual>
      <geometry>
        <mesh filename="package://qronk_description/meshes/shoulder_BR.stl" scale="0.001 0.001 0.001"/>
      </geometry>
      <origin rpy="0 0 0" xyz="0 0 0"/>
      <material name="grey"/>
    </visual>
    <collision>
      <geometry>
        <box size="0.05 0.04 0.068"/>
      </geometry>
      <origin rpy="0 0 0" xyz="-0.03 0 -0.005"/>
    </collision>
    <inertial>
      <origin rpy="0 0 0" xyz="-0.03 0 -0.005"/>
      <mass value="0.1"/>
      <inertia ixx="5.936666666666668e-05" ixy="0" ixz="0" iyy="3.416666666666667e-05" iyz="0" izz="5.186666666666667e-05"/>
    </inertial>
  </link>
  <joint name="shoulder_upper_leg_BR_joint" type="revolute">
    <parent link="shoulder_BR_link"/>
    <child link="upper_leg_BR_link"/>
    <origin rpy="0 0 0" xyz="-0.03 -0.0214 -0.00002"/>
    <axis xyz="0 1 0"/>
    <limit effort="100" lower="-3.141592653589793" upper="3.141592653589793" velocity="100"/>
  </joint>
  <link name="upper_leg_BR_link">
    <visual>
      <geometry>
        <mesh filename="package://qronk_description/meshes/upper_leg_BR.stl" scale="0.001 0.001 0.001"/>
      </geometry>
      <origin rpy="0 0 0" xyz="0 0 0"/>
      <material name="grey"/>
    </visual>
    <collision>
      <geometry>
        <box size="0.05 0.0532 0.137"/>
      </geometry>
      <origin rpy="0 0 0" xyz="-0 -0.0266 -0.0435"/>
    </collision>
    <inertial>
      <origin rpy="0 0 0" xyz="-0 -0.0266 -0.0435"/>
      <mass value="0.1"/>
      <inertia ixx="2.239741666666667e-05" ixy="0" ixz="0" iyy="4.441866666666667e-05" iyz="0" izz="2.5149416666666667e-05"/>
    </inertial>
  </link>
  <joint name="upper_leg_lower_leg_BR_joint" type="revolute">
    <parent link="upper_leg_BR_link"/>
    <child link="lower_leg_BR_link"/>
    <origin rpy="0 0 0" xyz="-0 -0.016349 -0.098459"/>
    <axis xyz="0 1 0"/>
    <limit effort="100" lower="-3.141592653589793" upper="3.141592653589793" velocity="100"/>
  </joint>
  <link name="lower_leg_BR_link">
    <visual>
      <geometry>
        <mesh filename="package://qronk_description/meshes/lower_leg_BR.stl" scale="0.001 0.001 0.001"/>
      </geometry>
      <origin rpy="0 0 0" xyz="0 0 0"/>
      <material name="grey"/>
    </visual>
    <collision>
      <geometry>
        <box size="0.028 0.0134 0.102"/>
      </geometry>
      <origin rpy="0 0 0" xyz="-0 -0.0067 -0.037"/>
    </collision>
    <inertial>
      <origin rpy="0 0 0" xyz="-0 -0.0067 -0.037"/>
      <mass value="0.1"/>
      <inertia ixx="9.323333333333333e-05" ixy="0" ixz="0" iyy="8.029666666666669e-06" iyz="0" izz="8.819633333333333e-05"/>
    </inertial>
  </link>
  <joint name="lower_leg_foot_BR_joint" type="fixed">
    <parent link="lower_leg_BR_link"/>
    <child link="foot_BR_link"/>
    <origin rpy="0 0 0" xyz="-0 -0.0066835 -0.09416"/>
  </joint>
  <link name="foot_BR_link">
    <visual>
      <geometry>
        <sphere radius="0.0075"/>
      </geometry>
      <origin rpy="0 0 0" xyz="0 0 0"/>
      <material name="grey"/>
    </visual>
    <collision>
      <geometry>
        <sphere radius="0.0075"/>
      </geometry>
      <origin rpy="0 0 0" xyz="0 0 0"/>
    </collision>
    <inertial>
      <origin rpy="0 0 0" xyz="0 0 0"/>
      <mass value="0.05"/>
      <inertia ixx="1.125e-06" ixy="0" ixz="0" iyy="1.125e-06" iyz="0" izz="1.125e-06"/>
    </inertial>
  </link>
  <joint name="chassis_shoulder_BL_joint" type="revolute">
    <parent link="chassis_link"/>
    <child link="shoulder_BL_link"/>
    <origin rpy="0 0 0" xyz="-0.0885 0.047417 0.000052"/>
    <axis xyz="1 0 0"/>
    <limit effort="100" lower="-3.141592653589793" upper="3.141592653589793" velocity="100"/>
  </joint>
  <link name="shoulder_BL_link">
    <visual>
      <geometry>
        <mesh filename="package://qronk_description/meshes/shoulder_BL.stl" scale="0.001 0.001 0.001"/>
      </geometry>
      <origin rpy="0 0 0" xyz="0 0 0"/>
      <material name="grey"/>
    </visual>
    <collision>
      <geometry>
        <box size="0.05 0.04 0.068"/>
      </geometry>
      <origin rpy="0 0 0" xyz="-0.03 -0 -0.005"/>
    </collision>
    <inertial>
      <origin rpy="0 0 0" xyz="-0.03 -0 -0.005"/>
      <mass value="0.1"/>
      <inertia ixx="5.936666666666668e-05" ixy="0" ixz="0" iyy="3.416666666666667e-05" iyz="0" izz="5.186666666666667e-05"/>
    </inertial>
  </link>
  <joint name="shoulder_upper_leg_BL_joint" type="revolute">
    <parent link="shoulder_BL_link"/>
    <child link="upper_leg_BL_link"/>
    <origin rpy="0 0 0" xyz="-0.03 0.0214 -0.00002"/>
    <axis xyz="0 1 0"/>
    <limit effort="100" lower="-3.141592653589793" upper="3.141592653589793" velocity="100"/>
  </joint>
  <link name="upper_leg_BL_link">
    <visual>
      <geometry>
        <mesh filename="package://qronk_description/meshes/upper_leg_BL.stl" scale="0.001 0.001 0.001"/>
      </geometry>
      <origin rpy="0 0 0" xyz="0 0 0"/>
      <material name="grey"/>
    </visual>
    <collision>
      <geometry>
        <box size="0.05 0.0532 0.137"/>
      </geometry>
      <origin rpy="0 0 0" xyz="-0 0.0266 -0.0435"/>
    </collision>
    <inertial>
      <origin rpy="0 0 0" xyz="-0 0.0266 -0.0435"/>
      <mass value="0.1"/>
      <inertia ixx="2.239741666666667e-05" ixy="0" ixz="0" iyy="4.441866666666667e-05" iyz="0" izz="2.5149416666666667e-05"/>
    </inertial>
  </link>
  <joint name="upper_leg_lower_leg_BL_joint" type="revolute">
    <parent link="upper_leg_BL_link"/>
    <child link="lower_leg_BL_link"/>
    <origin rpy="0 0 0" xyz="-0 0.016349 -0.098459"/>
    <axis xyz="0 1 0"/>
    <limit effort="100" lower="-3.141592653589793" upper="3.141592653589793" velocity="100"/>
  </joint>
  <link name="lower_leg_BL_link">
    <visual>
      <geometry>
        <mesh filename="package://qronk_description/meshes/lower_leg_BL.stl" scale="0.001 0.001 0.001"/>
      </geometry>
      <origin rpy="0 0 0" xyz="0 0 0"/>
      <material name="grey"/>
    </visual>
    <collision>
      <geometry>
        <box size="0.028 0.0134 0.102"/>
      </geometry>
      <origin rpy="0 0 0" xyz="-0 0.0067 -0.037"/>
    </collision>
    <inertial>
      <origin rpy="0 0 0" xyz="-0 0.0067 -0.037"/>
      <mass value="0.1"/>
      <inertia ixx="9.323333333333333e-05" ixy="0" ixz="0" iyy="8.029666666666669e-06" iyz="0" izz="8.819633333333333e-05"/>
    </inertial>
  </link>
  <joint name="lower_leg_foot_BL_joint" type="fixed">
    <parent link="lower_leg_BL_link"/>
    <child link="foot_BL_link"/>
    <origin rpy="0 0 0" xyz="-0 0.0066835 -0.09416"/>
  </joint>
  <link name="foot_BL_link">
    <visual>
      <geometry>
        <sphere radius="0.0075"/>
      </geometry>
      <origin rpy="0 0 0" xyz="0 0 0"/>
      <material name="grey"/>
    </visual>
    <collision>
      <geometry>
        <sphere radius="0.0075"/>
      </geometry>
      <origin rpy="0 0 0" xyz="0 0 0"/>
    </collision>
    <inertial>
      <origin rpy="0 0 0" xyz="0 0 0"/>
      <mass value="0.05"/>
      <inertia ixx="1.125e-06" ixy="0" ixz="0" iyy="1.125e-06" iyz="0" izz="1.125e-06"/>
    </inertial>
  </link>
  <!-- chassis.xacro materials -->
  <gazebo reference="chassis_link">
    <material>Gazebo/Grey</material>
  </gazebo>
  <gazebo reference="battery_link">
    <material>Gazebo/Grey</material>
  </gazebo>
  <gazebo reference="raspberry_link">
    <material>Gazebo/Grey</material>
  </gazebo>
  <!-- leg_FR.xacro materials -->
  <gazebo reference="shoulder_FR_link">
    <material>Gazebo/Grey</material>
  </gazebo>
  <gazebo reference="upper_leg_FR_link">
    <material>Gazebo/Grey</material>
  </gazebo>
  <gazebo reference="lower_leg_FR_link">
    <material>Gazebo/Grey</material>
  </gazebo>
  <gazebo reference="foot_FR_link">
    <material>Gazebo/Grey</material>
  </gazebo>
  <!-- leg_FL.xacro materials -->
  <gazebo reference="shoulder_FL_link">
    <material>Gazebo/Grey</material>
  </gazebo>
  <gazebo reference="upper_leg_FL_link">
    <material>Gazebo/Grey</material>
  </gazebo>
  <gazebo reference="lower_leg_FL_link">
    <material>Gazebo/Grey</material>
  </gazebo>
  <gazebo reference="foot_FL_link">
    <material>Gazebo/Grey</material>
  </gazebo>
  <!-- leg_BR.xacro materials -->
  <gazebo reference="shoulder_BR_link">
    <material>Gazebo/Grey</material>
  </gazebo>
  <gazebo reference="upper_leg_BR_link">
    <material>Gazebo/Grey</material>
  </gazebo>
  <gazebo reference="lower_leg_BR_link">
    <material>Gazebo/Grey</material>
  </gazebo>
  <gazebo reference="foot_BR_link">
    <material>Gazebo/Grey</material>
  </gazebo>
  <!-- leg_BL.xacro materials -->
  <gazebo reference="shoulder_BL_link">
    <material>Gazebo/Grey</material>
  </gazebo>
  <gazebo reference="upper_leg_BL_link">
    <material>Gazebo/Grey</material>
  </gazebo>
  <gazebo reference="lower_leg_BL_link">
    <material>Gazebo/Grey</material>
  </gazebo>
  <gazebo reference="foot_BL_link">
    <material>Gazebo/Grey</material>
  </gazebo>
  <!-- Gazebo plugins for servo joints -->
  <!-- Refer to https://github.com/ros-simulation/gazebo_ros_pkgs/tree/ros2/gazebo_plugins/include/gazebo_plugins -->
  <gazebo>
    <plugin filename="libgazebo_ros_joint_state_publisher.so" name="joint_state_publisher">
      <!-- Update rate in Hertz -->
      <update_rate>10</update_rate>
      <!-- Name of joints in the model whose states will be published. -->
      <joint_name>chassis_shoulder_FR_joint</joint_name>
      <joint_name>shoulder_upper_leg_FR_joint</joint_name>
      <joint_name>upper_leg_lower_leg_FR_joint</joint_name>
      <joint_name>lower_leg_foot_FR_joint</joint_name>
      <joint_name>chassis_shoulder_FL_joint</joint_name>
      <joint_name>shoulder_upper_leg_FL_joint</joint_name>
      <joint_name>upper_leg_lower_leg_FL_joint</joint_name>
      <joint_name>lower_leg_foot_FL_joint</joint_name>
      <joint_name>chassis_shoulder_BR_joint</joint_name>
      <joint_name>shoulder_upper_leg_BR_joint</joint_name>
      <joint_name>upper_leg_lower_leg_BR_joint</joint_name>
      <joint_name>lower_leg_foot_BR_joint</joint_name>
      <joint_name>chassis_shoulder_BL_joint</joint_name>
      <joint_name>shoulder_upper_leg_BL_joint</joint_name>
      <joint_name>upper_leg_lower_leg_BL_joint</joint_name>
      <joint_name>lower_leg_foot_BL_joint</joint_name>
    </plugin>
  </gazebo>
  <gazebo>
    <plugin filename="libgazebo_ros_joint_pose_trajectory.so" name="joint_pose_trajectory">
      <!-- Update rate in Hz -->
      <update_rate>2</update_rate>
    </plugin>
  </gazebo>
  <!-- <xacro:include filename="imu.xacro" /> -->
</robot>
