<?xml version="1.0"?>
<robot xmlns:xacro="http://www.ros.org/wiki/xacro">

    <joint name="chassis_shoulder_FL_joint" type="revolute">

        <parent link="chassis_link" />
        <child link="shoulder_FL_link" />
        <origin xyz="0.0885 0.047417 0.000052" rpy="0 0 0" />
        <axis xyz="1 0 0" />
        <limit lower="${-pi}" upper="${pi}" effort="100" velocity="100" />

    </joint>

    <link name="shoulder_FL_link">

        <visual>
            <geometry>
                <mesh filename="file://$(find qronk_description)/meshes/shoulder_FL.stl"
                    scale="0.001 0.001 0.001" />
            </geometry>
            <origin xyz="0 0 0" rpy="0 0 0" />
            <material name="grey" />
        </visual>

        <collision>
            <geometry>
                <box size="0.05 0.04 0.068" />
            </geometry>
            <origin xyz="0.03 -0 -0.005" rpy="0 0 0" />
        </collision>

        <xacro:box_inertia m="0.1" l="0.05" w="0.04" h="0.068"
            xyz="0.03 -0 -0.005" rpy="0 0 0" />

    </link>

    <joint name="shoulder_upper_leg_FL_joint" type="revolute">

        <parent link="shoulder_FL_link" />
        <child link="upper_leg_FL_link" />
        <origin xyz="0.03 0.0214 -0.00002" rpy="0 0 0" />
        <axis xyz="0 1 0" />
        <limit lower="${-pi}" upper="${pi}" effort="100" velocity="100" />

    </joint>

    <link name="upper_leg_FL_link">

        <visual>
            <geometry>
                <mesh filename="file://$(find qronk_description)/meshes/upper_leg_FL.stl"
                    scale="0.001 0.001 0.001" />
            </geometry>
            <origin xyz="0 0 0" rpy="0 0 0" />
            <material name="grey" />
        </visual>

        <collision>
            <geometry>
                <box size="0.05 0.0532 0.137" />
            </geometry>
            <origin xyz="0 0.0266 -0.0435" rpy="0 0 0" />
        </collision>

        <xacro:box_inertia m="0.1" l="0.05" w="0.0532" h="0.0137"
            xyz="0 0.0266 -0.0435" rpy="0 0 0" />

    </link>

    <joint name="upper_leg_lower_leg_FL_joint" type="revolute">

        <parent link="upper_leg_FL_link" />
        <child link="lower_leg_FL_link" />
        <origin xyz="0 0.016349 -0.098459" rpy="0 0 0" />
        <axis xyz="0 1 0" />
        <limit lower="${-pi}" upper="${pi}" effort="100" velocity="100" />
        
    </joint>

    <link name="lower_leg_FL_link">

        <visual>
            <geometry>
                <mesh filename="file://$(find qronk_description)/meshes/lower_leg_FL.stl"
                    scale="0.001 0.001 0.001" />
            </geometry>
            <origin xyz="0 0 0" rpy="0 0 0" />
            <material name="grey" />
        </visual>

        <collision>
            <geometry>
                <box size="0.028 0.0134 0.102" />
            </geometry>
            <origin xyz="0 0.0067 -0.037" rpy="0 0 0" />
        </collision>

        <xacro:box_inertia m="0.1" l="0.028" w="0.0134" h="0.102"
            xyz="0 0.0067 -0.037" rpy="0 0 0" />

    </link>

    <joint name="lower_leg_foot_FL_joint" type="fixed">

        <parent link="lower_leg_FL_link" />
        <child link="foot_FL_link" />
        <origin xyz="0 0.0066835 -0.09416" rpy="0 0 0" />

    </joint>

    <link name="foot_FL_link">

        <visual>
            <geometry>
                <sphere radius="0.0075" />
            </geometry>
            <origin xyz="0 0 0" rpy="0 0 0" />
            <material name="grey" />
        </visual>

        <collision>
            <geometry>
                <sphere radius="0.0075" />
            </geometry>
            <origin xyz="0 0 0" rpy="0 0 0" />
        </collision>

        <xacro:sphere_inertia m="0.05" r="0.0075"
            xyz="0 0 0" rpy="0 0 0" />
        
    </link>

</robot>